[ 2023-11-03 00:12:40,947 ] 241 django.request - ERROR - Internal Server Error: /team-summary/
Traceback (most recent call last):
  File "E:\django_project\env\lib\site-packages\django\core\handlers\exception.py", line 55, in inner
    response = get_response(request)
  File "E:\django_project\env\lib\site-packages\django\core\handlers\base.py", line 197, in _get_response
    response = wrapped_callback(request, *callback_args, **callback_kwargs)
  File "E:\django_project\env\lib\site-packages\django\views\generic\base.py", line 104, in view
    return self.dispatch(request, *args, **kwargs)
  File "E:\django_project\env\lib\site-packages\django\views\generic\base.py", line 143, in dispatch
    return handler(request, *args, **kwargs)
  File "E:\django_project\env\lib\site-packages\django\views\generic\list.py", line 154, in get
    self.object_list = self.get_queryset()
  File "E:\django_project\match_tournament\tournament\views.py", line 64, in get_queryset
    queryset = Team.objects.annotate(
  File "E:\django_project\env\lib\site-packages\django\db\models\manager.py", line 87, in manager_method
    return getattr(self.get_queryset(), name)(*args, **kwargs)
  File "E:\django_project\env\lib\site-packages\django\db\models\query.py", line 1590, in annotate
    return self._annotate(args, kwargs, select=True)
  File "E:\django_project\env\lib\site-packages\django\db\models\query.py", line 1638, in _annotate
    clone.query.add_annotation(
  File "E:\django_project\env\lib\site-packages\django\db\models\sql\query.py", line 1133, in add_annotation
    annotation = annotation.resolve_expression(self, allow_joins=True, reuse=None)
  File "E:\django_project\env\lib\site-packages\django\db\models\aggregates.py", line 64, in resolve_expression
    c = super().resolve_expression(query, allow_joins, reuse, summarize)
  File "E:\django_project\env\lib\site-packages\django\db\models\expressions.py", line 950, in resolve_expression
    c.source_expressions[pos] = arg.resolve_expression(
  File "E:\django_project\env\lib\site-packages\django\db\models\expressions.py", line 1459, in resolve_expression
    c.cases[pos] = case.resolve_expression(
  File "E:\django_project\env\lib\site-packages\django\db\models\expressions.py", line 1382, in resolve_expression
    c.condition = c.condition.resolve_expression(
  File "E:\django_project\env\lib\site-packages\django\db\models\query_utils.py", line 87, in resolve_expression
    clause, joins = query._add_q(
  File "E:\django_project\env\lib\site-packages\django\db\models\sql\query.py", line 1576, in _add_q
    child_clause, needed_inner = self.build_filter(
  File "E:\django_project\env\lib\site-packages\django\db\models\sql\query.py", line 1491, in build_filter
    condition = self.build_lookup(lookups, col, value)
  File "E:\django_project\env\lib\site-packages\django\db\models\sql\query.py", line 1312, in build_lookup
    lhs = self.try_transform(lhs, lookup_name)
  File "E:\django_project\env\lib\site-packages\django\db\models\sql\query.py", line 1356, in try_transform
    raise FieldError(
django.core.exceptions.FieldError: Unsupported lookup 'matches_won' for ManyToOneRel or join on the field not permitted.
[ 2023-11-03 00:15:22,542 ] 266 django.utils.autoreload - INFO - E:\django_project\match_tournament\tournament\views.py changed, reloading.
