[ 2023-11-02 22:39:42,972 ] 241 django.request - WARNING - Not Found: /team/<int:pk>
[ 2023-11-02 22:41:00,293 ] 241 django.request - ERROR - Internal Server Error: /team/1/
Traceback (most recent call last):
  File "E:\django_project\env\lib\site-packages\django\core\handlers\exception.py", line 55, in inner
    response = get_response(request)
  File "E:\django_project\env\lib\site-packages\django\core\handlers\base.py", line 197, in _get_response
    response = wrapped_callback(request, *callback_args, **callback_kwargs)
  File "E:\django_project\env\lib\site-packages\django\views\generic\base.py", line 104, in view
    return self.dispatch(request, *args, **kwargs)
  File "E:\django_project\env\lib\site-packages\django\views\generic\base.py", line 143, in dispatch
    return handler(request, *args, **kwargs)
  File "E:\django_project\env\lib\site-packages\django\views\generic\detail.py", line 108, in get
    self.object = self.get_object()
  File "E:\django_project\env\lib\site-packages\django\views\generic\detail.py", line 53, in get_object
    obj = queryset.get()
  File "E:\django_project\env\lib\site-packages\django\db\models\query.py", line 633, in get
    num = len(clone)
  File "E:\django_project\env\lib\site-packages\django\db\models\query.py", line 380, in __len__
    self._fetch_all()
  File "E:\django_project\env\lib\site-packages\django\db\models\query.py", line 1881, in _fetch_all
    self._result_cache = list(self._iterable_class(self))
  File "E:\django_project\env\lib\site-packages\django\db\models\query.py", line 91, in __iter__
    results = compiler.execute_sql(
  File "E:\django_project\env\lib\site-packages\django\db\models\sql\compiler.py", line 1549, in execute_sql
    sql, params = self.as_sql()
  File "E:\django_project\env\lib\site-packages\django\db\models\sql\compiler.py", line 736, in as_sql
    extra_select, order_by, group_by = self.pre_sql_setup(
  File "E:\django_project\env\lib\site-packages\django\db\models\sql\compiler.py", line 84, in pre_sql_setup
    self.setup_query(with_col_aliases=with_col_aliases)
  File "E:\django_project\env\lib\site-packages\django\db\models\sql\compiler.py", line 73, in setup_query
    self.select, self.klass_info, self.annotation_col_map = self.get_select(
  File "E:\django_project\env\lib\site-packages\django\db\models\sql\compiler.py", line 279, in get_select
    related_klass_infos = self.get_related_selections(select, select_mask)
  File "E:\django_project\env\lib\site-packages\django\db\models\sql\compiler.py", line 1367, in get_related_selections
    raise FieldError(
django.core.exceptions.FieldError: Invalid field name(s) given in select_related: 'team_matches'. Choices are: (none)
[ 2023-11-02 22:41:10,300 ] 241 django.request - ERROR - Internal Server Error: /team/02/
Traceback (most recent call last):
  File "E:\django_project\env\lib\site-packages\django\core\handlers\exception.py", line 55, in inner
    response = get_response(request)
  File "E:\django_project\env\lib\site-packages\django\core\handlers\base.py", line 197, in _get_response
    response = wrapped_callback(request, *callback_args, **callback_kwargs)
  File "E:\django_project\env\lib\site-packages\django\views\generic\base.py", line 104, in view
    return self.dispatch(request, *args, **kwargs)
  File "E:\django_project\env\lib\site-packages\django\views\generic\base.py", line 143, in dispatch
    return handler(request, *args, **kwargs)
  File "E:\django_project\env\lib\site-packages\django\views\generic\detail.py", line 108, in get
    self.object = self.get_object()
  File "E:\django_project\env\lib\site-packages\django\views\generic\detail.py", line 53, in get_object
    obj = queryset.get()
  File "E:\django_project\env\lib\site-packages\django\db\models\query.py", line 633, in get
    num = len(clone)
  File "E:\django_project\env\lib\site-packages\django\db\models\query.py", line 380, in __len__
    self._fetch_all()
  File "E:\django_project\env\lib\site-packages\django\db\models\query.py", line 1881, in _fetch_all
    self._result_cache = list(self._iterable_class(self))
  File "E:\django_project\env\lib\site-packages\django\db\models\query.py", line 91, in __iter__
    results = compiler.execute_sql(
  File "E:\django_project\env\lib\site-packages\django\db\models\sql\compiler.py", line 1549, in execute_sql
    sql, params = self.as_sql()
  File "E:\django_project\env\lib\site-packages\django\db\models\sql\compiler.py", line 736, in as_sql
    extra_select, order_by, group_by = self.pre_sql_setup(
  File "E:\django_project\env\lib\site-packages\django\db\models\sql\compiler.py", line 84, in pre_sql_setup
    self.setup_query(with_col_aliases=with_col_aliases)
  File "E:\django_project\env\lib\site-packages\django\db\models\sql\compiler.py", line 73, in setup_query
    self.select, self.klass_info, self.annotation_col_map = self.get_select(
  File "E:\django_project\env\lib\site-packages\django\db\models\sql\compiler.py", line 279, in get_select
    related_klass_infos = self.get_related_selections(select, select_mask)
  File "E:\django_project\env\lib\site-packages\django\db\models\sql\compiler.py", line 1367, in get_related_selections
    raise FieldError(
django.core.exceptions.FieldError: Invalid field name(s) given in select_related: 'team_matches'. Choices are: (none)
[ 2023-11-02 22:43:57,391 ] 266 django.utils.autoreload - INFO - E:\django_project\match_tournament\tournament\views.py changed, reloading.
