[ 2023-11-02 23:06:00,802 ] 241 django.request - ERROR - Internal Server Error: /team/1/
Traceback (most recent call last):
  File "E:\django_project\env\lib\site-packages\django\core\handlers\exception.py", line 55, in inner
    response = get_response(request)
  File "E:\django_project\env\lib\site-packages\django\core\handlers\base.py", line 220, in _get_response
    response = response.render()
  File "E:\django_project\env\lib\site-packages\django\template\response.py", line 114, in render
    self.content = self.rendered_content
  File "E:\django_project\env\lib\site-packages\django\template\response.py", line 92, in rendered_content
    return template.render(context, self._request)
  File "E:\django_project\env\lib\site-packages\django\template\backends\django.py", line 61, in render
    return self.template.render(context)
  File "E:\django_project\env\lib\site-packages\django\template\base.py", line 175, in render
    return self._render(context)
  File "E:\django_project\env\lib\site-packages\django\template\base.py", line 167, in _render
    return self.nodelist.render(context)
  File "E:\django_project\env\lib\site-packages\django\template\base.py", line 1005, in render
    return SafeString("".join([node.render_annotated(context) for node in self]))
  File "E:\django_project\env\lib\site-packages\django\template\base.py", line 1005, in <listcomp>
    return SafeString("".join([node.render_annotated(context) for node in self]))
  File "E:\django_project\env\lib\site-packages\django\template\base.py", line 966, in render_annotated
    return self.render(context)
  File "E:\django_project\env\lib\site-packages\django\template\base.py", line 1064, in render
    output = self.filter_expression.resolve(context)
  File "E:\django_project\env\lib\site-packages\django\template\base.py", line 715, in resolve
    obj = self.var.resolve(context)
  File "E:\django_project\env\lib\site-packages\django\template\base.py", line 847, in resolve
    value = self._resolve_lookup(context)
  File "E:\django_project\env\lib\site-packages\django\template\base.py", line 914, in _resolve_lookup
    current = current()
  File "E:\django_project\match_tournament\tournament\models.py", line 14, in matches_won
    return self.team_matches.filter(won=True).count()
  File "E:\django_project\env\lib\site-packages\django\db\models\manager.py", line 87, in manager_method
    return getattr(self.get_queryset(), name)(*args, **kwargs)
  File "E:\django_project\env\lib\site-packages\django\db\models\query.py", line 1436, in filter
    return self._filter_or_exclude(False, args, kwargs)
  File "E:\django_project\env\lib\site-packages\django\db\models\query.py", line 1454, in _filter_or_exclude
    clone._filter_or_exclude_inplace(negate, args, kwargs)
  File "E:\django_project\env\lib\site-packages\django\db\models\query.py", line 1461, in _filter_or_exclude_inplace
    self._query.add_q(Q(*args, **kwargs))
  File "E:\django_project\env\lib\site-packages\django\db\models\sql\query.py", line 1545, in add_q
    clause, _ = self._add_q(q_object, self.used_aliases)
  File "E:\django_project\env\lib\site-packages\django\db\models\sql\query.py", line 1576, in _add_q
    child_clause, needed_inner = self.build_filter(
  File "E:\django_project\env\lib\site-packages\django\db\models\sql\query.py", line 1426, in build_filter
    lookups, parts, reffed_expression = self.solve_lookup_type(arg, summarize)
  File "E:\django_project\env\lib\site-packages\django\db\models\sql\query.py", line 1236, in solve_lookup_type
    _, field, _, lookup_parts = self.names_to_path(lookup_splitted, self.get_meta())
  File "E:\django_project\env\lib\site-packages\django\db\models\sql\query.py", line 1724, in names_to_path
    raise FieldError(
django.core.exceptions.FieldError: Cannot resolve keyword 'won' into field. Choices are: batting_overs, batting_score, batting_wickets, id, match, match_id, team, team_id
[ 2023-11-02 23:07:56,960 ] 266 django.utils.autoreload - INFO - E:\django_project\match_tournament\tournament\models.py changed, reloading.
